<mujocoinclude>
    <body name="hand" childclass="franka_hand" quat="0 0 0 1">
      <inertial mass="0.73" pos="-0.01 0 0.03" fullinertia="0.001 0.0025 0.0017 0.0 0.0 0.0"/>
      <geom mesh="hand_0" material="off_white" class="finger_vis"/>
      <geom mesh="hand_1" material="black" class="finger_vis"/>
      <geom mesh="hand_2" material="black" class="finger_vis"/>
      <geom mesh="hand_3" material="white" class="finger_vis"/>
      <geom mesh="hand_4" material="off_white" class="finger_vis"/>
      <geom mesh="hand_c" class="finger_coll"/>
      <body name="hand_tcp" pos="0 0 0.1034" quat="0 0 0 1">
        <site name="ee_site" pos="0 0 0" type="box" size="0.001 0.001 0.001" rgba="1 1 0 0"/>
        <!-- 원래는 hand_tcp_site : 임의로 ee_site라고 바꿈 -->
      </body>
      <body name="left_finger" pos="0 0 0.0584">
        <inertial mass="0.015" pos="0 0 0" diaginertia="2.375e-6 2.375e-6 7.5e-7"/>
        <joint name="finger_joint1" class="finger"/>
        <geom mesh="finger_0" material="off_white" class="finger_vis"/>
        <geom mesh="finger_1" material="black" class="finger_vis"/>
        <geom mesh="finger_0" class="finger_coll"/>
        <geom class="fingertip_pad_collision_1"/>
        <geom class="fingertip_pad_collision_2"/>
        <geom class="fingertip_pad_collision_3"/>
        <geom class="fingertip_pad_collision_4"/>
        <geom class="fingertip_pad_collision_5"/>
      </body>
      <body name="right_finger" pos="0 0 0.0584" quat="0 0 0 1">
        <inertial mass="0.015" pos="0 0 0" diaginertia="2.375e-6 2.375e-6 7.5e-7"/>
        <joint name="finger_joint2" class="finger"/>
        <geom mesh="finger_0" material="off_white" class="finger_vis"/>
        <geom mesh="finger_1" material="black" class="finger_vis"/>
        <geom mesh="finger_0" class="finger_coll"/>
        <geom class="fingertip_pad_collision_1"/>
        <geom class="fingertip_pad_collision_2"/>
        <geom class="fingertip_pad_collision_3"/>
        <geom class="fingertip_pad_collision_4"/>
        <geom class="fingertip_pad_collision_5"/>
      </body>
    </body>
</mujocoinclude>
