<!-- /home/minjun/wr_ws/src/welding_robot/dm_ros/dm_ros/robots/welding_scene2.xml-->
<mujoco model="welding_scene2">

    <option timestep="0.002" gravity="0 0 -9.81"/>
  
    <default>
        <geom type="box" condim="1" friction="0.8 0.1 0.1" rgba="0.6 0.6 0.6 1"/>
    </default>

    <!-- fr3 & common asset -->
    <include file="common/assets.xml"/>
    <include file="common/sensor.xml"/>
    <include file="fr3/assets.xml"/>
    <include file="franka_hand/assets.xml"/>
    <!-- ðŸ”§ ìš©ì ‘ í† ì¹˜ ì—ì…‹ ì¶”ê°€ -->
    <include file="welding_torch/assets.xml"/>
    <include file="fr3/actuator.xml"/>
    <include file="franka_hand/actuator.xml"/>

    <!-- common scene for welding -->
    <worldbody>
    
        <!-- light/ë°”ë‹¥ ì •ì˜ -->
        <include file="common/scene.xml" />        
        
        <!-- Franka ë¡œë´‡ ë¶ˆëŸ¬ì˜¤ê¸° (í† ì¹˜ê°€ í¬í•¨ëœ ë²„ì „) -->
        <include file="fr3/fr3_hand_torch_urdf.xml"/>

        <!-- welding í™˜ê²½ -->    
        <!-- í…Œì´ë¸” (í™•ìž¥ëœ í¬ê¸°, ë¬´ìž‘ìœ„í™”ë¥¼ ìœ„í•œ ê¸°ë³¸ ìœ„ì¹˜) -->
        <body name="table" pos="0.5 0 0.45" euler="0 0 0"> 
            <!-- ì›í˜• í…Œì´ë¸”ë¡œ ë³€ê²½ (ë” ë„“ì€ ìž‘ì—… ê³µê°„) -->
            <geom name="table_top" type="cylinder" size="0.25 0.02" pos="0 0 0.02" rgba="0.3 0.3 0.3 1" contype="2" conaffinity="2"/>
            
            <!-- Extended Lap joint (ë” ê¸´ ê²½ë¡œ) -->
            <body name="lap_base" pos="-0.15 -0.15 0.04">
                <geom type="box" size="0.15 0.06 0.005" rgba="0.6 0.2 0.2 1" contype="2" conaffinity="2"/>
                <joint type="hinge" axis="0 0 1" pos="0 0 0.005" limited="true" range="-0.1 0.1"/>
                <body name="lap_top" pos="0.05 0.03 0.005">
                    <geom type="box" size="0.15 0.06 0.005" rgba="0.8 0.3 0.3 1" contype="2" conaffinity="2"/>
                    <!-- í™•ìž¥ëœ ìš©ì ‘ ê²½ë¡œ (start -> waypoints -> end) -->
                    <site name="lap_start" pos="-0.15 -0.06 0.005" size="0.003" rgba="1 0 0 1"/>
                    <site name="lap_waypoint1" pos="-0.08 -0.03 0.005" size="0.003" rgba="1 0.5 0 1"/>
                    <site name="lap_waypoint2" pos="0 0 0.005" size="0.003" rgba="0.5 0.5 0 1"/>
                    <site name="lap_waypoint3" pos="0.08 0.03 0.005" size="0.003" rgba="0 0.5 0 1"/>
                    <site name="lap_end" pos="0.15 0.06 0.005" size="0.003" rgba="0 1 0 1"/>
                    <joint type="hinge" axis="0 0 1" pos="0 0 0.005" limited="true" range="-0.1 0.1"/>
                </body>
            </body>

            <!-- Fillet weld joint (íšŒì „ëœ Tìží˜•) -->
            <body name="fillet_joint_base" pos="0.18 0.1 0.04" euler="0 0 0.7854">
                <geom type="box" size="0.12 0.025 0.005" rgba="0.2 0.2 0.8 1" contype="2" conaffinity="2"/>
                <joint type="hinge" axis="0 0 1" pos="0 0 0.005" limited="true" range="-0.1 0.1"/>
                <body name="fillet_joint_vertical" pos="0 0 0.015">
                    <geom type="box" size="0.025 0.12 0.005" pos="0 0 0.025" rgba="0.2 0.2 0.8 1" contype="2" conaffinity="2"/>
                    <joint type="hinge" axis="0 0 1" pos="0 0 0.005" limited="true" range="-0.1 0.1"/>
                </body>
            </body>

            <!-- ê³¡ë©´ íŒŒì´í”„ (cylinder) -->
            <body name="curved_pipe" pos="-0.05 0.2 0.04" euler="0 1.57 0">
                <geom type="cylinder" size="0.025 0.15" rgba="0.1 0.6 0.1 1" contype="2" conaffinity="2"/>
                <joint type="hinge" axis="0 0 1" pos="0 0 0.005" limited="true" range="-0.1 0.1"/>
            </body>
            
            <!-- ìž¥ì• ë¬¼ 1: ì›€ì§ì´ëŠ” êµ¬ì²´ (ìž‘ì—…ìžì˜ ì† ì‹œë®¬ë ˆì´ì…˜) -->
            <body name="moving_obstacle" pos="0.1 0 0.15">
                <joint name="obstacle_x" type="slide" axis="1 0 0" limited="true" range="-0.1 0.1"/>
                <joint name="obstacle_y" type="slide" axis="0 1 0" limited="true" range="-0.1 0.1"/>
                <joint name="obstacle_z" type="slide" axis="0 0 1" limited="true" range="-0.05 0.05"/>
                <geom name="obstacle_sphere" type="sphere" size="0.04" rgba="0.9 0.9 0.2 0.8" contype="2" conaffinity="2"/>
                <!-- ì†ê°€ë½ ëª¨ì–‘ ì¶”ê°€ -->
                <body name="finger1" pos="0.04 0 0">
                    <geom type="capsule" size="0.01 0.03" rgba="0.9 0.8 0.7 1" contype="2" conaffinity="2"/>
                </body>
            </body>
            
            <!-- ìž¥ì• ë¬¼ 2: ì •ì  ìž¥ì• ë¬¼ (ìš©ì ‘ í´ëž¨í”„) -->
            <body name="static_clamp1" pos="-0.12 0.08 0.04">
                <geom type="box" size="0.02 0.02 0.05" rgba="0.4 0.4 0.4 1" contype="2" conaffinity="2"/>
                <body name="clamp_arm1" pos="0 0 0.05">
                    <geom type="box" size="0.04 0.01 0.01" rgba="0.5 0.5 0.5 1" contype="2" conaffinity="2"/>
                </body>
            </body>
            
            <!-- ìž¥ì• ë¬¼ 3: ì‚°ì—…ìš© ë„êµ¬ (ë“œë¦´ ë¨¸ì‹  ëª¨í˜•) -->
            <body name="tool_obstacle" pos="0.15 -0.1 0.04">
                <geom type="cylinder" size="0.03 0.08" rgba="0.2 0.7 0.2 1" contype="2" conaffinity="2"/>
                <body name="tool_tip" pos="0 0 0.08">
                    <geom type="cylinder" size="0.01 0.03" rgba="0.8 0.8 0.8 1" contype="2" conaffinity="2"/>
                </body>
            </body>
            
            <!-- ìž¥ì• ë¬¼ 4: ìž‘ì—…ìž ëª¨í˜• (ê°„ë‹¨í•œ ì¸ì²´ ìƒë°˜ì‹ ) -->
            <body name="worker_torso" pos="0.0 -0.25 0.1">
                <!-- ëª¸í†µ -->
                <geom type="capsule" size="0.08 0.15" pos="0 0 0" rgba="0.2 0.3 0.6 1" contype="2" conaffinity="2"/>
                <!-- ë¨¸ë¦¬ -->
                <body name="worker_head" pos="0 0 0.2">
                    <geom type="sphere" size="0.06" rgba="0.9 0.8 0.7 1" contype="2" conaffinity="2"/>
                </body>
                <!-- ì™¼íŒ” -->
                <body name="worker_left_arm" pos="-0.1 0 0.1">
                    <geom type="capsule" size="0.03 0.12" euler="0 1.2 0" rgba="0.9 0.8 0.7 1" contype="2" conaffinity="2"/>
                </body>
                <!-- ì˜¤ë¥¸íŒ” -->
                <body name="worker_right_arm" pos="0.1 0 0.1">
                    <geom type="capsule" size="0.03 0.12" euler="0 -1.2 0" rgba="0.9 0.8 0.7 1" contype="2" conaffinity="2"/>
                </body>
            </body>
        </body>
    </worldbody>
    
    <!-- í‚¤í”„ë ˆìž„ ì¶”ê°€ (ì›¨ì´í¬ì¸íŠ¸ í¬í•¨) 
    <keyframe>
        <key name="home" qpos="0 0 0 -1.57 0 1.57 0.785 0 0 0 0 0 0 0 0 0 0 0 0 0 0 0 0"/>
        <key name="lap_start_pose" qpos="-0.0313527 -0.5176165 -0.4489684 -2.2359937 -0.0756571 -2.2178279 -0.3668594 0 0 0 0 0 0 0 0 0 0 0 0 0 0 0 0"/>
        <key name="lap_end_pose" qpos="-0.0214813 -0.7660105 -0.3266952 -2.4520914 -0.0856292 -2.2117574 -0.4996434 0 0 0 0 0 0 0 0 0 0 0 0 0 0 0 0"/>
    </keyframe>-->
</mujoco>

