<mujoco>
  
    <asset>
      <texture name="plane" type="2d" builtin="checker" rgb1=".2 .3 .4" rgb2=".1 0.15 0.2" width="256" height="256" mark="cross" markrgb=".8 .8 .8" />
      <material name="plane" reflectance="0.3" texture="plane" texrepeat="1 1" texuniform="true" />
    </asset>
  
    <worldbody>
        <light directional="true" diffuse=".2 .2 .2" specular="0 0 0" pos="0 1 5" dir="0 -1 -1" castshadow="false"/>
        <light directional="false" diffuse=".8 .8 .8" specular="0.3 0.3 0.3" pos="0 -1 4" dir="0 0 -1" />
        <light directional="true" diffuse="0 0 0" specular=".7 .7 .7" pos="0 3 3" dir="0 -3 -3" />
        <geom name="floor" pos="0 0 -.0" group="1" size="0 0 .1" type="plane" material="plane" condim="3" />

        <body name="box_1" pos="-0.5 0 0.1">
            <geom type="box" size="0.1 0.1 0.1" rgba="1.0 0 0 1"/>
            <joint type="hinge" axis="0 0 1"/>
        </body>

        <body name="box_2" pos="0 0 0.1">
            <geom type="box" size="0.1 0.1 0.1" rgba="0 0 1 1"/>
            <joint type="slide" axis="1 0 0"/>
            <joint type="slide" axis="0 1 0"/>
        </body>
    </worldbody>
</mujoco>
  
