<mujoco>
    <option gravity="0 0 -9.81" integrator="Euler" timestep="0.001"/>
    
    <asset>
      <texture name="plane" type="2d" builtin="checker" rgb1=".2 .3 .4" rgb2=".1 0.15 0.2" width="256" height="256" mark="cross" markrgb=".8 .8 .8" />
      <material name="plane" reflectance="0.3" texture="plane" texrepeat="1 1" texuniform="true" />
    </asset>
  
    <worldbody>
        <light directional="true" diffuse=".2 .2 .2" specular="0 0 0" pos="0 1 5" dir="0 -1 -1" castshadow="false"/>
        <light directional="false" diffuse=".8 .8 .8" specular="0.3 0.3 0.3" pos="0 -1 4" dir="0 0 -1" />
        <light directional="true" diffuse="0 0 0" specular=".7 .7 .7" pos="0 3 3" dir="0 -3 -3" />
        <geom name="floor" pos="0 0 -.0" group="1" size="0 0 .1" type="plane" material="plane" condim="3" />

    <!-- 충돌 발생: box_1과 ball_1 -->
        <body name="box_1" pos="-0.5 0 0.1">
            <geom type="box" size="0.1 0.1 0.1" rgba="1 0 0 0.3" contype="1" conaffinity="1"/>
            <joint type="hinge" axis="0 0 1"/>
        </body>
        
        <body name="ball_1" pos="-0.5 0 1">
            <geom type="sphere" size="0.1" rgba="0 1 0 1" contype="1" conaffinity="1"/>
            <joint type="free"/>
        </body>

    <!-- 충돌 무시: box_2와 ball_2 -->
        <body name="box_2" pos="0 0 0.1">
            <geom type="box" size="0.1 0.1 0.1" rgba="0 0 1 0.3" contype="1" conaffinity="2"/>
            <joint type="slide" axis="1 0 0"/>
            <joint type="slide" axis="0 1 0"/>
        </body>

        <body name="ball_2" pos="0 0 1">
            <geom type="sphere" size="0.1" rgba="0 1 0 1" contype="1" conaffinity="4"/>
            <!--- 위 geom : box_2와 ball_2 충돌 X /// 아래 geom : box_2와 ball_2 충돌 ㅇ 
            <geom type="sphere" size="0.1" rgba="0 1 0 1" contype="1" conaffinity="3"/> 
            -->
            <joint type="free"/>
        </body>        
    </worldbody>
</mujoco>


