<mujoco>
  <compiler angle="degree"/>

  <asset>
    <texture name="plane" type="2d" builtin="checker" rgb1=".2 .3 .4" rgb2=".1 0.15 0.2" width="256" height="256" mark="cross" markrgb=".8 .8 .8" />
    <material name="plane" reflectance="0.0" texture="plane" texrepeat="1 1" texuniform="true" />
  </asset>


  <worldbody>
    <geom name="floor" pos="0 0 -.0" group="1" size="0 0 .1" type="plane" material="plane" condim="3" />

    <body name="base">
      <body name="link1" pos="0 0 0.0">
        <geom type='box' size="0.05 0.05 0.3" pos="0 0 0.3" mass="0.5" rgba="0.9 0.3 0.3 1.0"/>
        <joint name="joint1" type="hinge" axis="0 0 1" pos="0 0 0" range="-180 180"/>
        <body name="link2" pos="0 0 0.6">
          <geom type="box" size="0.05 0.05 0.5" pos="0 0 0.3" mass="0.3" rgba="0.3 0.0 0.9 1.0" />
          <joint name="joint2" type="hinge" axis="1 0 0" pos="0 0 0" range="-180 180"/>
        </body>
      </body>
    </body>

    <body name="box" pos="0.2 0 0.5">
      <geom type="box" size="0.05 0.05 0.05" rgba="0.3 0.9 0.3 1.0"/>
      <joint name="box_joint" type="free"/>
    </body>
  </worldbody>

  <actuator>
    <position joint="joint1" kp="300" ctrlrange="-180 180"/>
    <position joint="joint2" kp="300" ctrlrange="-180 180"/>
  </actuator>
</mujoco>
