<mujocoinclude>
  <compiler angle="radian" meshdir="mesh"/>

  <option integrator="implicitfast"/>

  <default>
    <default class="fr3">
      <joint armature="0.1" damping="1"/>
      <position inheritrange="1"/>
      <default class="visual">
        <geom type="mesh" group="2" contype="0" conaffinity="0"/>
      </default>
      <default class="collision">
        <geom type="mesh" group="3" mass="0" density="0"/>
      </default>
      <site size="0.001" rgba="0.5 0.5 0.5 0.3" group="4"/>
    </default>
  </default>

  <asset>
    <material name="black" rgba=".2 .2 .2 1"/>
    <material name="white" rgba="1 1 1 1"/>
    <material name="red" rgba="1 0.072272 0.039546 1"/>
    <material name="gray" rgba="0.863156 0.863156 0.863157 1"/>
    <material name="button_green" rgba="0.102241 0.571125 0.102242 1"/>
    <material name="button_red" rgba="0.520996 0.008023 0.013702 1"/>
    <material name="button_blue" rgba="0.024157 0.445201 0.737911 1"/>

    <mesh file="link0_0.obj"/>
    <mesh file="link0_1.obj"/>
    <mesh file="link0_2.obj"/>
    <mesh file="link0_3.obj"/>
    <mesh file="link0_4.obj"/>
    <mesh file="link0_5.obj"/>
    <mesh file="link0_6.obj"/>
    <mesh file="link1.obj"/>
    <mesh file="link2.obj"/>
    <mesh file="link3_0.obj"/>
    <mesh file="link3_1.obj"/>
    <mesh file="link4_0.obj"/>
    <mesh file="link4_1.obj"/>
    <mesh file="link5_0.obj"/>
    <mesh file="link5_1.obj"/>
    <mesh file="link5_2.obj"/>
    <mesh file="link6_0.obj"/>
    <mesh file="link6_1.obj"/>
    <mesh file="link6_2.obj"/>
    <mesh file="link6_3.obj"/>
    <mesh file="link6_4.obj"/>
    <mesh file="link6_5.obj"/>
    <mesh file="link6_6.obj"/>
    <mesh file="link6_7.obj"/>
    <mesh file="link7_0.obj"/>
    <mesh file="link7_1.obj"/>
    <mesh file="link7_2.obj"/>
    <mesh file="link7_3.obj"/>

    <mesh name="link0_coll" file="link0.stl"/>
    <mesh name="link1_coll" file="link1.stl"/>
    <mesh name="link2_coll" file="link2.stl"/>
    <mesh name="link3_coll" file="link3.stl"/>
    <mesh name="link4_coll" file="link4.stl"/>
    <mesh name="link5_coll" file="link5.stl"/>
    <mesh name="link6_coll" file="link6.stl"/>
    <mesh name="link7_coll" file="link7.stl"/>
  </asset>

  <worldbody>
    <body name="base" childclass="fr3">
      <body name="fr3_link0">
        <inertial mass="0.629769" pos="-0.041018 -0.00014 0.049974" fullinertia="0.00315 0.00388 0.004285 8.2904e-7 0.00015 8.2299e-6"/>
        <geom mesh="link0_0" material="black" class="visual"/>
        <geom mesh="link0_1" material="white" class="visual"/>
        <geom mesh="link0_2" material="white" class="visual"/>
        <geom mesh="link0_3" material="white" class="visual"/>
        <geom mesh="link0_4" material="white" class="visual"/>
        <geom mesh="link0_5" material="red" class="visual"/>
        <geom mesh="link0_6" material="black" class="visual"/>
        <geom name="fr3_link0_collision" mesh="link0_coll" class="collision"/>
        <body name="fr3_link1" pos="0 0 0.333">
          <inertial mass="4.970684" pos="0.003875 0.002081 -0.04762"  fullinertia="0.70337 0.70661 0.0091170 -0.00013900 0.0067720 0.019169"/>
          <joint name="fr3_joint1" axis="0 0 1" range="-2.8972 2.8972" actuatorfrcrange="-87 87"/> 
          <geom name="fr3_link1_collision" class="collision" mesh="link1_coll"/>
          <geom material="white" mesh="link1" class="visual"/>
          <body name="fr3_link2" quat="1 -1 0 0">
            <inertial mass = "0.646926" pos="-0.003141 -0.02872  0.003495" fullinertia="0.0079620 2.8110e-2 2.5995e-2 -3.925e-3 1.0254e-2 7.04e-4"/>
            <joint name="fr3_joint2" axis="0 0 1" range="-1.8326 1.8326" actuatorfrcrange="-87 87"/>
            <geom material="white" mesh="link2" class="visual"/>
            <geom name="fr3_link2_collision" class="collision" mesh="link2_coll"/>
            <body name="fr3_link3" pos="0 -0.316 0" quat="1 1 0 0">
              <inertial mass="3.228604" pos="2.7518e-2 3.9252e-2 -6.6502e-2" fullinertia="3.7242e-2 3.6155e-2 1.083e-2 -4.761e-3 -1.1396e-2 -1.2805e-2"/>
              <joint name="fr3_joint3" axis="0 0 1" range="-2.8972 2.8972" actuatorfrcrange="-87 87"/>
              <geom mesh="link3_0" material="white" class="visual"/>
              <geom mesh="link3_1" material="black" class="visual"/>
              <geom name="fr3_link3_collision" class="collision" mesh="link3_coll"/>
              <body name="fr3_link4" pos="0.0825 0 0" quat="1 1 0 0">
                <inertial mass="3.587895" pos="-5.317e-2 1.04419e-1 2.7454e-2" fullinertia="2.5853e-2 1.9552e-2 2.8323e-2 7.796e-3 -1.332e-3 8.641e-3"/>
                <joint name="fr3_joint4" axis="0 0 1" range="-3.0718 -0.1222" actuatorfrcrange="-87 87"/>
                <geom mesh="link4_0" material="white" class="visual"/>
                <geom mesh="link4_1" material="black" class="visual"/>
                <geom name="fr3_link4_collision" class="collision" mesh="link4_coll"/>
                <body name="fr3_link5" pos="-0.0825 0.384 0" quat="1 -1 0 0">
                  <inertial mass="1.225946" pos="-1.1953e-2 4.1065e-2 -3.8437e-2" fullinertia="3.5549e-2 2.9474e-2 8.627e-3 -2.117e-3 -4.037e-3 2.29e-4"/>
                  <joint name="fr3_joint5" axis="0 0 1" range="-2.8798 2.8798" actuatorfrcrange="-12 12"/> 
                  <geom mesh="link5_0" material="white" class="visual"/>
                  <geom mesh="link5_1" material="white" class="visual"/>
                  <geom mesh="link5_2" material="black" class="visual"/>
                  <geom name="fr3_link5_collision" class="collision" mesh="link5_coll"/>
                  <body name="fr3_link6" quat="1 1 0 0">
                    <inertial mass="1.666555" pos="6.0149e-2 -1.4117e-2 -1.0517e-2" fullinertia="1.964e-3 4.354e-3 5.433e-3 1.09e-4 -1.158e-3 3.41e-4"/>
                    <joint name="fr3_joint6" axis="0 0 1" range="0.4363 4.6251" actuatorfrcrange="-12 12"/> 
                    <geom mesh="link6_0" material="button_green" class="visual"/>
                    <geom mesh="link6_1" material="white" class="visual"/>
                    <geom mesh="link6_2" material="white" class="visual"/>
                    <geom mesh="link6_3" material="gray" class="visual"/>
                    <geom mesh="link6_4" material="button_red" class="visual"/>
                    <geom mesh="link6_5" material="white" class="visual"/>
                    <geom mesh="link6_6" material="black" class="visual"/>
                    <geom mesh="link6_7" material="button_blue" class="visual"/>
                    <geom name="fr3_link6_collision" class="collision" mesh="link6_coll"/>
                    <body name="fr3_link7" pos="0.088 0 0" quat="1 1 0 0">
                      <inertial mass="7.35522e-01" pos="1.0517e-2 -4.252e-3 6.1597e-2" fullinertia="1.2516e-2 1.0027e-2 4.815e-3 -4.28e-4 -1.196e-3 -7.41e-4"/>
                      <joint name="fr3_joint7" axis="0 0 1" range="-3.0543 3.0543" actuatorfrcrange="-12 12"/>
                      <geom mesh="link7_0" material="black" class="visual"/>
                      <geom mesh="link7_1" material="white" class="visual"/>
                      <geom mesh="link7_2" material="white" class="visual"/>
                      <geom mesh="link7_3" material="black" class="visual"/>
                      <geom name="fr3_link7_collision" class="collision" mesh="link7_coll"/>
                      <site name="flange_site" pos="0 0 0.107"/>
                    </body>
                  </body>
                </body>
              </body>
            </body>
          </body>
        </body>
      </body>
    </body>
  </worldbody>

  <actuator>
    <position class="fr3" name="fr3_joint1" joint="fr3_joint1" kp="4500" kv="450"/>
    <position class="fr3" name="fr3_joint2" joint="fr3_joint2" kp="4500" kv="450"/>
    <position class="fr3" name="fr3_joint3" joint="fr3_joint3" kp="3500" kv="350"/>
    <position class="fr3" name="fr3_joint4" joint="fr3_joint4" kp="3500" kv="350"/>
    <position class="fr3" name="fr3_joint5" joint="fr3_joint5" kp="2000" kv="200"/>
    <position class="fr3" name="fr3_joint6" joint="fr3_joint6" kp="2000" kv="200"/>
    <position class="fr3" name="fr3_joint7" joint="fr3_joint7" kp="2000" kv="200"/>
  </actuator>

  <keyframe>
    <key name="home" qpos="0 0 0 -1.57079 0 1.57079 -0.7853" ctrl="0 0 0 -1.57079 0 1.57079 -0.7853"/>
  </keyframe>
</mujocoinclude>
