<?xml version="1.0" ?>
<!-- =================================================================================== -->
<!-- |    This document was autogenerated by xacro from /workspaces/src/franka_description/robots/fr3/fr3.urdf.xacro | -->
<!-- |    EDITING THIS FILE BY HAND IS NOT RECOMMENDED                                 | -->
<!-- =================================================================================== -->
<robot name="fr3_hand">
  <!-- safety_distance: Minimum safety distance in [m] by which the collision volumes are expanded and which is enforced during robot motions -->
  <!-- arm_id: Namespace of the robot arm. Serves to differentiate between arms in case of multiple instances. -->
  <!-- joint_limits: description of the joint limits that comes from a YAML file. Example definition: ${xacro.load_yaml('$(find franka_description)/robots/fr3/joint_limits.yaml')} -->
  <!-- kinematics: description of the kinematics that comes from a YAML file. Example definition: ${xacro.load_yaml('$(find franka_description)/robots/fr3/kinematics.yaml')} -->
  <!-- inertials: description of the inertials that comes from a YAML file. Example definition: ${xacro.load_yaml('$(find franka_description)/robots/fr3/inertials.yaml')} -->
  <!-- dynamics: description of the dynamics that comes from a YAML file. Example definition: ${xacro.load_yaml('$(find franka_description)/robots/fr3/dynamics.yaml')} -->
  <link name="base">
      </link>
  <joint name="fr3_base_joint" type="fixed">
    <parent link="base"/>
    <child link="fr3_link0"/>
    <origin  xyz="0 0 0"/>
  </joint>
  <!-- sub-link defining detailed meshes for collision with environment -->
  <link name="fr3_link0">
    <visual name="fr3_link0_visual">
      <geometry>
        <mesh filename="package://franka_description/meshes/robot_arms/fr3/visual/link0.dae"/>
      </geometry>
    </visual>
    <collision name="fr3_link0_collision">
      <geometry>
        <mesh filename="package://franka_description/meshes/robot_arms/fr3/collision/link0.stl"/>
      </geometry>
    </collision>
    <inertial>
      <origin xyz="-0.041018 0.00014 0.049974"/>
      <mass value="0.629769"/>
      <inertia ixx="0.00315" ixy="8.2904e-7" ixz="0.00015" iyy="0.00388" iyz="8.2299e-6" izz="0.004285"/>        
    </inertial>
  </link>
  <!-- sub-link defining detailed meshes for collision with environment -->
  <link name="fr3_link1">
    <visual name="fr3_link1_visual">
      <geometry>
        <mesh filename="package://franka_description/meshes/robot_arms/fr3/visual/link1.dae"/>
      </geometry>
    </visual>
    <collision name="fr3_link1_collision">
      <geometry>
        <mesh filename="package://franka_description/meshes/robot_arms/fr3/collision/link1.stl"/>
      </geometry>
    </collision>
    <inertial>
      <origin xyz="0.003875 0.002081 -0.04762"/>
      <mass value="4.970684"/>
      <inertia ixx="0.70337" ixy="-0.00013900" ixz="0.0067720" iyy="0.70661" iyz="0.019169" izz="0.0091170"/>
    </inertial>
  </link>
  <joint name="fr3_mani_joint1" type="revolute">
    <origin  xyz="0 0 0.333"/>
    <parent link="fr3_link0"/>
    <child link="fr3_link1"/>
    <axis xyz="0 0 1"/>
    <limit effort="87.0" lower="-2.8972" upper="2.8972" velocity="2.62"/>
    <!-- <safety_controller k_position="100.0" k_velocity="40.0" soft_lower_limit="-2.7437" soft_upper_limit="2.7437"/> -->
    <!-- <dynamics D="1" K="7000" damping="0.003" friction="0.2" mu_coulomb="0" mu_viscous="16"/> -->
  </joint>
  <!-- sub-link defining detailed meshes for collision with environment -->
  <link name="fr3_link2">
    <visual name="fr3_link2_visual">
      <geometry>
        <mesh filename="package://franka_description/meshes/robot_arms/fr3/visual/link2.dae"/>
      </geometry>
    </visual>
    <collision name="fr3_link2_collision">
      <geometry>
        <mesh filename="package://franka_description/meshes/robot_arms/fr3/collision/link2.stl"/>
      </geometry>
    </collision>
    <inertial>
      <origin xyz="-0.003141 -0.02872  0.003495"/>
      <mass value="0.646926"/>
      <inertia ixx="0.0079620" ixy="-3.925e-3" ixz="1.0254e-2" iyy="2.8110e-2" iyz="7.04e-4" izz="2.5995e-2"/>
    </inertial>
  </link>
  <joint name="fr3_mani_joint2" type="revolute">
    <origin rpy="-1.570796326794897 0 0" xyz="0 0 0"/>
    <parent link="fr3_link1"/>
    <child link="fr3_link2"/>
    <axis xyz="0 0 1"/>
    <limit effort="87.0" lower="-1.8326" upper="1.8326" velocity="2.62"/>
    <!-- <safety_controller k_position="100.0" k_velocity="40.0" soft_lower_limit="-1.7837" soft_upper_limit="1.7837"/> -->
    <!-- <dynamics D="1" K="7000" damping="0.003" friction="0.2" mu_coulomb="0" mu_viscous="16"/> -->
  </joint>
  <!-- sub-link defining detailed meshes for collision with environment -->
  <link name="fr3_link3">
    <visual name="fr3_link3_visual">
      <geometry>
        <mesh filename="package://franka_description/meshes/robot_arms/fr3/visual/link3.dae"/>
      </geometry>
    </visual>
    <collision name="fr3_link3_collision">
      <geometry>
        <mesh filename="package://franka_description/meshes/robot_arms/fr3/collision/link3.stl"/>
      </geometry>
    </collision>
    <inertial>
      <origin xyz="2.7518e-2 3.9252e-2 -6.6502e-2"/>
      <mass value="3.228604"/>
      <inertia ixx="3.7242e-2" ixy="-4.761e-3" ixz="-1.1396e-2" iyy="3.6155e-2" iyz="-1.2805e-2" izz="1.083e-2"/>
    </inertial>
  </link>
  <joint name="fr3_mani_joint3" type="revolute">
    <origin rpy="1.570796326794897 0 0" xyz="0 -0.316 0"/>
    <parent link="fr3_link2"/>
    <child link="fr3_link3"/>
    <axis xyz="0 0 1"/>
    <limit effort="87.0" lower="-2.8972" upper="2.8972" velocity="2.62"/>
    <!-- <safety_controller k_position="100.0" k_velocity="40.0" soft_lower_limit="-2.9007" soft_upper_limit="2.9007"/> -->
    <!-- <dynamics D="1" K="7000" damping="0.003" friction="0.2" mu_coulomb="0" mu_viscous="16"/> -->
  </joint>
  <!-- sub-link defining detailed meshes for collision with environment -->
  <link name="fr3_link4">
    <visual name="fr3_link4_visual">
      <geometry>
        <mesh filename="package://franka_description/meshes/robot_arms/fr3/visual/link4.dae"/>
      </geometry>
    </visual>
    <collision name="fr3_link4_collision">
      <geometry>
        <mesh filename="package://franka_description/meshes/robot_arms/fr3/collision/link4.stl"/>
      </geometry>
    </collision>
    <inertial>
      <origin xyz="-5.317e-2 1.04419e-1 2.7454e-2"/>
      <mass value="3.587895"/>
      <inertia ixx="2.5853e-2" ixy="7.796e-3" ixz="-1.332e-3" iyy="1.9552e-2" iyz="8.641e-3" izz="2.8323e-2"/>
    </inertial>
  </link>
  <joint name="fr3_mani_joint4" type="revolute">
    <origin rpy="1.570796326794897 0 0" xyz="0.0825 0 0"/>
    <parent link="fr3_link3"/>
    <child link="fr3_link4"/>
    <axis xyz="0 0 1"/>
    <limit effort="87.0" lower="-3.0718" upper="-0.1222" velocity="2.62"/>
    <!-- <safety_controller k_position="100.0" k_velocity="40.0" soft_lower_limit="-3.0421" soft_upper_limit="-0.1518"/>
    <dynamics D="1" K="7000" damping="0.003" friction="0.2" mu_coulomb="0" mu_viscous="16"/> -->
  </joint>
  <!-- sub-link defining detailed meshes for collision with environment -->
  <link name="fr3_link5">
    <visual name="fr3_link5_visual">
      <geometry>
        <mesh filename="package://franka_description/meshes/robot_arms/fr3/visual/link5.dae"/>
      </geometry>
    </visual>
    <collision name="fr3_link5_collision">
      <geometry>
        <mesh filename="package://franka_description/meshes/robot_arms/fr3/collision/link5.stl"/>
      </geometry>
    </collision>
    <inertial>
      <origin  xyz="-1.1953e-2 4.1065e-2 -3.8437e-2"/>
      <mass value="1.225946"/>
      <inertia ixx="3.5549e-2" ixy="-2.117e-3" ixz="-4.037e-3" iyy="2.9474e-2" iyz="2.29e-4" izz="8.627e-3"/>
    </inertial>
  </link>
  <joint name="fr3_mani_joint5" type="revolute">
    <origin rpy="-1.570796326794897 0 0" xyz="-0.0825 0.384 0"/>
    <parent link="fr3_link4"/>
    <child link="fr3_link5"/>
    <axis xyz="0 0 1"/>
    <limit effort="12.0" lower="-2.8798" upper="2.8798" velocity="5.26"/>
    <!-- <safety_controller k_position="100.0" k_velocity="40.0" soft_lower_limit="-2.8065" soft_upper_limit="2.8065"/>
    <dynamics D="1" K="7000" damping="0.003" friction="0.2" mu_coulomb="0" mu_viscous="16"/> -->
  </joint>
  <!-- sub-link defining detailed meshes for collision with environment -->
  <link name="fr3_link6">
    <visual name="fr3_link6_visual">
      <geometry>
        <mesh filename="package://franka_description/meshes/robot_arms/fr3/visual/link6.dae"/>
      </geometry>
    </visual>
    <collision name="fr3_link6_collision">
      <geometry>
        <mesh filename="package://franka_description/meshes/robot_arms/fr3/collision/link6.stl"/>
      </geometry>
    </collision>
    <inertial>
      <origin xyz="6.0149e-2 -1.4117e-2 -1.0517e-2"/>
      <mass value="1.666555"/>
      <inertia ixx="1.964e-3" ixy="1.09e-4" ixz="-1.158e-3" iyy="4.354e-3" iyz="3.41e-4" izz="5.433e-3"/>
    </inertial>
  </link>
  <joint name="fr3_mani_joint6" type="revolute">
    <origin rpy="1.570796326794897 0 0" xyz="0 0 0"/>
    <parent link="fr3_link5"/>
    <child link="fr3_link6"/>
    <axis xyz="0 0 1"/>
    <limit effort="12.0" lower="0.4363" upper="4.6251" velocity="4.18"/>
    <safety_controller k_position="100.0" k_velocity="40.0" soft_lower_limit="0.5445" soft_upper_limit="4.5169"/>
    <dynamics D="1" K="7000" damping="0.003" friction="0.2" mu_coulomb="0" mu_viscous="16"/>
  </joint>
  <!-- sub-link defining detailed meshes for collision with environment -->
  <link name="fr3_link7">
    <visual name="fr3_link7_visual">
      <geometry>
        <mesh filename="package://franka_description/meshes/robot_arms/fr3/visual/link7.dae"/>
      </geometry>
    </visual>
    <collision name="fr3_link7_collision">
      <geometry>
        <mesh filename="package://franka_description/meshes/robot_arms/fr3/collision/link7.stl"/>
      </geometry>
    </collision>
    <inertial>
      <origin xyz="1.0517e-2 -4.252e-3 6.1597e-2"/>
      <mass value="7.35522e-01"/>
      <inertia ixx="1.2516e-2" ixy="-4.28e-4" ixz="-1.196e-3" iyy="1.0027e-2" iyz="-7.41e-4" izz="4.815e-3"/>
    </inertial>
  </link>
  <joint name="fr3_mani_joint7" type="revolute">
    <origin rpy="1.570796326794897 0 0" xyz="0.088 0 0"/>
    <parent link="fr3_link6"/>
    <child link="fr3_link7"/>
    <axis xyz="0 0 1"/>
    <limit effort="12.0" lower="-3.0543" upper="3.0543" velocity="5.26"/>
    <safety_controller k_position="100.0" k_velocity="40.0" soft_lower_limit="-3.0159" soft_upper_limit="3.0159"/>
    <dynamics D="1" K="7000" damping="0.003" friction="0.2" mu_coulomb="0" mu_viscous="16"/>
  </joint>
  <link name="fr3_link8"/>
  <joint name="fr3_mani_joint8" type="fixed">
    <origin  xyz="0 0 0.107"/>
    <parent link="fr3_link7"/>
    <child link="fr3_link8"/>
  </joint>
  <joint name="fr3_hand_joint" type="fixed">
    <parent link="fr3_link8"/>
    <child link="fr3_hand"/>
    <origin rpy="0 0 -0.7853981633974483" xyz="0 0 0"/>
  </joint>
  <!-- sub-link defining detailed meshes for collision with environment -->
  <link name="fr3_hand">
    <visual name="fr3_hand_visual">
      <geometry>
        <mesh filename="package://franka_description/meshes/robot_ee/franka_hand_white/visual/hand.dae"/>
      </geometry>
    </visual>
    <collision name="fr3_hand_collision">
      <geometry>
        <mesh filename="package://franka_description/meshes/robot_ee/franka_hand_white/collision/hand.stl"/>
      </geometry>
    </collision>
    <inertial>
      <origin  xyz="-0.01 0 0.03"/>
      <mass value="0.73"/>
      <inertia ixx="0.001" ixy="0" ixz="0" iyy="0.0025" iyz="0" izz="0.0017"/>    
    </inertial>
  </link>
  <!-- Define the hand_tcp frame -->
  <link name="hand_tcp"/>
  <joint name="hand_tcp_joint" type="fixed">
    <origin  xyz="0 0 0.1034"/>
    <parent link="fr3_hand"/>
    <child link="hand_tcp"/>
  </joint>
  <link name="fr3_leftfinger">
    <visual name="fr3_leftfinger_visual">
      <geometry>
        <mesh filename="package://franka_description/meshes/robot_ee/franka_hand_white/visual/finger.dae"/>
      </geometry>
    </visual>
    <!-- screw mount -->
    <collision>
      <origin  xyz="0 18.5e-3 11e-3"/>
      <geometry>
        <box size="22e-3 15e-3 20e-3"/>
      </geometry>
    </collision>
    <!-- cartriage sledge -->
    <collision>
      <origin  xyz="0 6.8e-3 2.2e-3"/>
      <geometry>
        <box size="22e-3 8.8e-3 3.8e-3"/>
      </geometry>
    </collision>
    <!-- diagonal finger -->
    <collision>
      <origin rpy="0.5235987755982988 0 0" xyz="0 15.9e-3 28.35e-3"/>
      <geometry>
        <box size="17.5e-3 7e-3 23.5e-3"/>
      </geometry>
    </collision>
    <!-- rubber tip with which to grasp -->
    <collision>
      <origin  xyz="0 7.58e-3 45.25e-3"/>
      <geometry>
        <box size="17.5e-3 15.2e-3 18.5e-3"/>
      </geometry>
    </collision>
  </link>
  <link name="fr3_rightfinger">
    <visual name="fr3_rightfinger_visual">
      <origin rpy="0 0 3.141592653589793" xyz="0 0 0"/>
      <geometry>
        <mesh filename="package://franka_description/meshes/robot_ee/franka_hand_white/visual/finger.dae"/>
      </geometry>
    </visual>
    <!-- screw mount -->
    <collision>
      <origin  xyz="0 -18.5e-3 11e-3"/>
      <geometry>
        <box size="22e-3 15e-3 20e-3"/>
      </geometry>
    </collision>
    <!-- cartriage sledge -->
    <collision>
      <origin  xyz="0 -6.8e-3 2.2e-3"/>
      <geometry>
        <box size="22e-3 8.8e-3 3.8e-3"/>
      </geometry>
    </collision>
    <!-- diagonal finger -->
    <collision>
      <origin rpy="-0.5235987755982988 0 0" xyz="0 -15.9e-3 28.35e-3"/>
      <geometry>
        <box size="17.5e-3 7e-3 23.5e-3"/>
      </geometry>
    </collision>
    <!-- rubber tip with which to grasp -->
    <collision>
      <origin  xyz="0 -7.58e-3 45.25e-3"/>
      <geometry>
        <box size="17.5e-3 15.2e-3 18.5e-3"/>
      </geometry>
    </collision>
  </link>
  <!-- <joint name="fr3_finger_joint1" type="prismatic"> -->
  <joint name="fr3_finger_joint1" type="fixed">
    <parent link="fr3_hand"/>
    <child link="fr3_leftfinger"/>
    <origin  xyz="0 0 0.0584"/>
    <axis xyz="0 1 0"/>
    <limit effort="100" lower="0.0" upper="0.04" velocity="0.2"/>
    <dynamics damping="0.3"/>
  </joint>
  <!-- <joint name="fr3_finger_joint2" type="prismatic"> -->
  <joint name="fr3_finger_joint2" type="fixed">
    <parent link="fr3_hand"/>
    <child link="fr3_rightfinger"/>
    <origin  xyz="0 0 0.0584"/>
    <axis xyz="0 -1 0"/>
    <limit effort="100" lower="0.0" upper="0.04" velocity="0.2"/>
    <mimic joint="fr3_finger_joint1"/>
    <dynamics damping="0.3"/>
  </joint>
</robot>