<mujocoinclude>
<body name="base" childclass="fr3">
    <body name="fr3_link0">
    <inertial mass="0.629769" pos="-0.041018 -0.00014 0.049974" fullinertia="0.00315 0.00388 0.004285 8.2904e-7 0.00015 8.2299e-6"/>
    <geom mesh="link0_0" material="black" class="visual"/>
    <geom mesh="link0_1" material="white" class="visual"/>
    <geom mesh="link0_2" material="white" class="visual"/>
    <geom mesh="link0_3" material="white" class="visual"/>
    <geom mesh="link0_4" material="white" class="visual"/>
    <!-- <geom mesh="link0_5" material="red" class="visual"/> -->
    <geom mesh="link0_6" material="black" class="visual"/>
    <geom name="fr3_link0_collision" mesh="link0_coll" class="collision"/>
    <body name="fr3_link1" pos="0 0 0.333">
        <inertial mass="4.970684" pos="0.003875 0.002081 -0.04762"  fullinertia="0.70337 0.70661 0.0091170 -0.00013900 0.0067720 0.019169"/>
        <joint name="fr3_joint1" axis="0 0 1" range="-2.8972 2.8972" actuatorfrcrange="-87 87"/>
        <site name="fr3_joint1" pos="0 0 0" type="box" size="0.1 0.1 0.001" rgba="1 0 0 1"/>
        <geom name="fr3_link1_collision" class="collision" mesh="link1_coll"/>
        <geom material="white" mesh="link1" class="visual"/>
        <body name="fr3_link2" quat="1 -1 0 0">
        <inertial mass = "0.646926" pos="-0.003141 -0.02872  0.003495" fullinertia="0.0079620 2.8110e-2 2.5995e-2 -3.925e-3 1.0254e-2 7.04e-4"/>
        <joint name="fr3_joint2" axis="0 0 1" range="-1.8326 1.8326" actuatorfrcrange="-87 87"/>
        <site name="fr3_joint2" pos="0 0 0" type="box" size="0.1 0.1 0.001" rgba="1 0 0 1"/>
        <geom material="white" mesh="link2" class="visual"/>
        <geom name="fr3_link2_collision" class="collision" mesh="link2_coll"/>
        <body name="fr3_link3" pos="0 -0.316 0" quat="1 1 0 0">
            <inertial mass="3.228604" pos="2.7518e-2 3.9252e-2 -6.6502e-2" fullinertia="3.7242e-2 3.6155e-2 1.083e-2 -4.761e-3 -1.1396e-2 -1.2805e-2"/>
            <joint name="fr3_joint3" axis="0 0 1" range="-2.8972 2.8972" actuatorfrcrange="-87 87"/>
            <site name="fr3_joint3" pos="0 0 0" type="box" size="0.1 0.1 0.001" rgba="1 0 0 1"/>
            <geom mesh="link3_0" material="white" class="visual"/>
            <geom mesh="link3_1" material="black" class="visual"/>
            <geom name="fr3_link3_collision" class="collision" mesh="link3_coll"/>
            <body name="fr3_link4" pos="0.0825 0 0" quat="1 1 0 0">
            <inertial mass="3.587895" pos="-5.317e-2 1.04419e-1 2.7454e-2" fullinertia="2.5853e-2 1.9552e-2 2.8323e-2 7.796e-3 -1.332e-3 8.641e-3"/>
            <joint name="fr3_joint4" axis="0 0 1" range="-3.0718 -0.1222" actuatorfrcrange="-87 87"/>
            <site name="fr3_joint4" pos="0 0 0" type="box" size="0.1 0.1 0.001" rgba="1 0 0 1"/>
            <geom mesh="link4_0" material="white" class="visual"/>
            <geom mesh="link4_1" material="black" class="visual"/>
            <geom name="fr3_link4_collision" class="collision" mesh="link4_coll"/>
            <body name="fr3_link5" pos="-0.0825 0.384 0" quat="1 -1 0 0">
                <inertial mass="1.225946" pos="-1.1953e-2 4.1065e-2 -3.8437e-2" fullinertia="3.5549e-2 2.9474e-2 8.627e-3 -2.117e-3 -4.037e-3 2.29e-4"/>
                <joint name="fr3_joint5" axis="0 0 1" range="-2.8798 2.8798" actuatorfrcrange="-12 12"/> 
                <site name="fr3_joint5" pos="0 0 0" type="box" size="0.1 0.1 0.001" rgba="1 0 0 1"/>
                <geom mesh="link5_0" material="white" class="visual"/>
                <geom mesh="link5_1" material="white" class="visual"/>
                <geom mesh="link5_2" material="black" class="visual"/>
                <geom name="fr3_link5_collision" class="collision" mesh="link5_coll"/>
                <body name="fr3_link6" quat="1 1 0 0">
                <inertial mass="1.666555" pos="6.0149e-2 -1.4117e-2 -1.0517e-2" fullinertia="1.964e-3 4.354e-3 5.433e-3 1.09e-4 -1.158e-3 3.41e-4"/>
                <joint name="fr3_joint6" axis="0 0 1" range="0.4363 4.6251" actuatorfrcrange="-12 12"/> 
                <site name="fr3_joint6" pos="0 0 0" type="box" size="0.1 0.1 0.001" rgba="1 0 0 1"/>
                <geom mesh="link6_0" material="button_green" class="visual"/>
                <geom mesh="link6_1" material="white" class="visual"/>
                <geom mesh="link6_2" material="white" class="visual"/>
                <geom mesh="link6_3" material="gray" class="visual"/>
                <geom mesh="link6_4" material="button_red" class="visual"/>
                <geom mesh="link6_5" material="white" class="visual"/>
                <geom mesh="link6_6" material="black" class="visual"/>
                <geom mesh="link6_7" material="button_blue" class="visual"/>
                <geom name="fr3_link6_collision" class="collision" mesh="link6_coll"/>
                <body name="fr3_link7" pos="0.088 0 0" quat="1 1 0 0">
                    <inertial mass="7.35522e-01" pos="1.0517e-2 -4.252e-3 6.1597e-2" fullinertia="1.2516e-2 1.0027e-2 4.815e-3 -4.28e-4 -1.196e-3 -7.41e-4"/>
                    <joint name="fr3_joint7" axis="0 0 1" range="-3.0543 3.0543" actuatorfrcrange="-12 12"/>
                    <site name="fr3_joint7" pos="0 0 0" type="box" size="0.1 0.1 0.001" rgba="1 0 0 1"/>
                    <geom mesh="link7_0" material="black" class="visual"/>
                    <geom mesh="link7_1" material="white" class="visual"/>
                    <geom mesh="link7_2" material="white" class="visual"/>
                    <geom mesh="link7_3" material="black" class="visual"/>
                    <geom name="fr3_link7_collision" class="collision" mesh="link7_coll"/>
                    <site name="flange_site" pos="0 0 0.107" type="box" size="0.1 0.1 0.001" rgba="0 1 0 1"/>
                    <body name="franka_hand" pos="0 0 0.107" quat="0.9238795 0 0 -0.3826834">
                        <include file="../franka_hand/franka_hand_urdf.xml"/>
                        <camera name="hand_eye" pos="0.1 0.0 0.000" euler="3.141592 0.218  0" mode="fixed" fovy="58"/>
                        <!-- <geom type="box" pos="0.1 0 0" size="0.0125 0.045 0.0125" euler="3.141592 0.218 0" rgba="0.8 0.2 0.2 1" /> -->
                    </body>
                </body>
                </body>
            </body>
            </body>
        </body>
        </body>
    </body>
    </body>
</body>

</mujocoinclude>
